Workbook

Sheet Data
C5: C1 | D5: C2 | E5: C3 | F5: C4 | H5: Fugas (15%) | I5: Patm (bar) | K5: Para el paso de presión manométrica a absoluta)
B6: Q(Kg/h) | C6: 679 | D6: 1359 | E6: 340 | F6: 2038 | H6: 1.15 | I6: 0.932 | K6: Ampliaciones no vamos a meter
B7: P[bar(g)] | C7: 4 | D7: 7 | E7: 7 | F7: 7
B10: Qcalculo | C10: =(C6+D6+E6+F6)*H6 -> 5078.4 | H10: Qcaldera | I10: 5400
H11: Pcaldera[bar(a)] | I11: 10
B12: Tª VS [ºC] | C12: 220 | H12: Pcalculo[bar(e)] | I12: =10-I6 -> 9.068

Sheet Red de vapor
B2: valor cte
AC3: Accesorios
AA4: Linea de condensados | AB4: Lreal(m) | AC4: Codos | AD4: T(recta) | AE4: T(derivación) | AF4: Dtanteo (mm) | AG4: Leq(m) | AH4: Lcálculo(m) | AI4: Pentrada [bar(g)] | AJ4: Psalida [bar(g)]
D5: Tramo Caldera-P | O5: Tramo P-C1 | Q5: heje[m] | R5: 1.0945 | AA5: Caldera-P | AB5: =$E$7 -> 12.74 | AC5: 0 | AD5: 0 | AE5: 0 | AF5: N/A | AG5: =$E$8 -> 2.548 | AH5: =$E$9 -> 15.288 | AI5: =$H$9 -> 9.068 | AJ5: =$AI6 -> 9.058
AA6: P-C1 | AB6: =$P$7 -> 88.189 | AC6: 2 | AD6: 1 | AE6: 0 | AF6: 60 | AG6: =$P$8 -> 9.24 | AH6: =$P$9 -> 97.429 | AI6: =$S$9 -> 9.058 | AJ6: =AI6-0.24 -> 8.818
D7: Lreal(m) | E7: 12.74 | F7: Perdida de carga | O7: Lreal(m) | P7: =40+45+2*$R$5+1 -> 88.189 | Q7: Perdida de carga | AA7: P-S | AB7: =$E$24 -> 106 | AC7: 1 | AD7: 0 | AE7: 2 | AF7: 120 | AG7: =$E$25 -> 25.44 | AH7: =$E$26 -> 131.44 | AI7: =$H$26 -> 9.058 | AJ7: =AI7-0.16 -> 8.898
D8: Leq | E8: =E7*0.2 -> 2.548 | H8: P[bar(g)] | I8: T[ºC] | O8: Leq | P8: =(2*(32*60)+1*(90*60))/1000 -> 9.24 | S8: P[bar(g)] | T8: T[ºC] | AA8: S-C2 | AB8: =$P$24 -> 25 | AC8: 0 | AD8: 0 | AE8: 0 | AF8: N/A | AG8: =$P$25 -> 5 | AH8: =$P$26 -> 30 | AI8: =$S$26 -> 8.9002963 | AJ8: =AI8-0.07 -> 8.8302963
D9: Lcálculo(m) | E9: =E7+E8 -> 15.288 | F9: Tabla | G9: Entrada con | H9: 9.068 | I9: 220 | O9: Lcálculo(m) | P9: =P7+P8 -> 97.429 | Q9: Tabla | R9: Entrada con | S9: 9.058 | T9: 220 | AA9: S-T | AB9: =$E$41 -> 60 | AC9: 0 | AD9: 1 | AE9: 1 | AF9: 120 | AG9: =(1*(90*50)+1*(60*50))/1000 -> 7.5 | AH9: =$E$43 -> 78 | AI9: =$H$43 -> 8.9002963 | AJ9: =AI9-0.12 -> 8.7802963
AA10: T-C3 | AB10: =$P$41 -> 15 | AC10: 0 | AD10: 0 | AF10: N/A | AG10: =$P$42 -> 3 | AH10: =$P$43 -> 18 | AI10: =$S$43 -> 8.7802963 | AJ10: =AI10-0.07 -> 8.7102963
D11: Respecto a la long eq en este caso al tener una tubería corta se puede hacer una estimación empírica donde la longitud equivalente es un 20 % de la longitud real | O11: Schedule 160 - 80 | AA11: T-C4 | AB11: =$E$58 -> 45 | AC11: 2 | AD11: 1 | AE11: 0 | AF11: 100 | AG11: =$E$59 -> 12.4 | AH11: =$E$60 -> 57.4 | AI11: =$H$60 -> 8.7802963 | AJ11: =AI11-0.09 -> 8.6902963
G12: Salida | H12: hvapor [KJ/Kg] | I12: vol. Espec [m3 /kg] | J12: calor específico [KJ/KG*K] | K12: visco dinamica [Mpa *s] | R12: Salida | S12: hvapor [KJ/Kg] | T12: vol. Espec [m3 /kg] | U12: calor específico [KJ/KG*K] | V12: visco dinamica [Mpa *s]
H13: 2875.16 | I13: 0.215124 | J13: 2.31419 | K13: 0.0167543 | S13: 2875.21 | T13: 0.215349 | U13: 2.31373 | V13: 0.0167545
AA14: Linea de condensados | AB14: Tubería seleccionada | AC14: Dinterior (mm) | AD14: v(m/s) | AE14: ∆P(bar)
F15: Calculos | Q15: Calculos | AA15: Caldera-P | AB15: =$D$19 -> Schedule 80 - 150 | AC15: 146.4 | AD15: 19.17 | AE15: =$AI5-$AJ5 -> 0.01
AA16: P-C1 | AB16: =$O$11 -> Schedule 160 - 80 | AC16: 66.6 | AD16: 18.93 | AE16: =$AI6-$AJ6 -> 0.24
F17: densidad relativa | G17: viscosidad cinemática | H17: Qtramo | I17: Qvolumétrico | Q17: densidad relativa | R17: viscosidad cinemática | S17: Qtramo | T17: Qvolumétrico | AA17: P-S | AB17: =$D$28 -> DIN 2448 - 125 | AC17: 131.7 | AD17: 20.28 | AE17: =$AI7-$AJ7 -> 0.16
F18: =1/I13 -> 4.6484818 | G18: =(K13*10^(-3))/(F18*10^(-6)) -> 3.604252 | H18: =Data!I10 -> 5400 | I18: =H18/F18 -> 1161.6696 | Q18: =1/T13 -> 4.643625 | R18: =(V13*10^(-3))/(Q18*10^(-6)) -> 3.6080648 | S18: =Data!$I$10-Data!$H$6*(Data!$D$6+Data!$E$6+Data!$F$6) -> 1102.45 | T18: =S18/Q18 -> 237.41151 | AA18: S-C2 | AB18: =$O$28 -> DIN 2448 - 80 | AC18: 82.5 | AD18: 21.45 | AE18: =$AI8-$AJ8 -> 0.07
D19: Schedule 80 - 150 | AA19: S-T | AB19: =$D$45 -> DIN 2448 - 100 | AC19: 107.1 | AD19: 20.79 | AE19: =$AI9-$AJ9 -> 0.12
AA20: T-C3 | AB20: =$O$45 -> Schedule 40 - 50 | AC20: 52.5 | AD20: 20.42 | AE20: =$AI10-$AJ10 -> 0.07
AA21: T-C4 | AB21: =$D$62 -> Schedule 40 - 100 | AC21: 102.3 | AD21: 20.11 | AE21: =$AI11-$AJ11 -> 0.09
D22: Tramo P-S | O22: Tramo S-C2
D24: Lreal(m) | E24: 106 | F24: Perdida de carga | O24: Lreal(m) | P24: 25 | Q24: Perdida de carga
D25: Leq | E25: =(2*(90*120)+1*(32*120))/1000 -> 25.44 | H25: P[bar(g)] | I25: T[ºC] | O25: Leq | P25: =0.2*P24 -> 5 | S25: P[bar(g)] | T25: T[ºC]
D26: Lcálculo(m) | E26: =E24+E25 -> 131.44 | F26: Tabla | G26: Entrada con | H26: 9.058 | I26: 220 | O26: Lcálculo(m) | P26: =P24+P25 -> 30 | Q26: Tabla | R26: Entrada con | S26: =9.058-0.157703738185884 -> 8.9002963 | T26: 220
D28: DIN 2448 - 125 | O28: DIN 2448 - 80
G29: Salida | H29: hvapor [KJ/Kg] | I29: vol. Espec [m3 /kg] | J29: calor específico [KJ/KG*K] | K29: visco dinamica [Mpa *s] | R29: Salida | S29: hvapor [KJ/Kg] | T29: vol. Espec [m3 /kg] | U29: calor específico [KJ/KG*K] | V29: visco dinamica [Mpa *s]
H30: 2875.21 | I30: 0.215349 | J30: 2.31373 | K30: 0.0167545 | S30: 2875.98 | T30: 0.219012 | U30: 2.30644 | V30: 0.0167587
F32: Calculos | Q32: Calculos
F34: densidad relativa | G34: viscosidad cinemática | H34: Qtramo | I34: Qvolumétrico | Q34: densidad relativa | R34: viscosidad cinemática | S34: Qtramo | T34: Qvolumétrico
F35: =1/I30 -> 4.643625 | G35: =(K30*10^(-3))/(F35*10^(-6)) -> 3.6080648 | H35: =Data!I10-Data!H6*(Data!C6) -> 4619.15 | I35: =H35/F35 -> 994.72933 | Q35: =1/T30 -> 4.5659599 | R35: =(V30*10^(-3))/(Q35*10^(-6)) -> 3.6703564 | S35: =Data!I10-Data!H6*(Data!C6+Data!E6+Data!F6) -> 1884.45 | T35: =S35/Q35 -> 412.71716
D39: Tramo S-T | O39: Tramo T-C3
D41: Lreal(m) | E41: 60 | F41: Perdida de carga | O41: Lreal(m) | P41: 15 | Q41: Perdida de carga
D42: Leq | E42: =(1*(90*120)+1*(60*120))/1000 -> 18 | H42: P[bar(g)] | I42: T[ºC] | O42: Leq | P42: =P41*0.2 -> 3 | S42: P[bar(g)] | T42: T[ºC]
D43: Lcálculo(m) | E43: =E41+E42 -> 78 | F43: Tabla | G43: Entrada con | H43: =$S$26 -> 8.9002963 | I43: 220 | O43: Lcálculo(m) | P43: =P41+P42 -> 18 | Q43: Tabla | R43: Entrada con | S43: =$H$43-0.12 -> 8.7802963 | T43: 220
D45: DIN 2448 - 100 | O45: Schedule 40 - 50
G46: Salida | H46: hvapor [KJ/Kg] | I46: vol. Espec [m3 /kg] | J46: calor específico [KJ/KG*K] | K46: visco dinamica [Mpa *s] | R46: Salida | S46: hvapor [KJ/Kg] | T46: vol. Espec [m3 /kg] | U46: calor específico [KJ/KG*K] | V46: visco dinamica [Mpa *s]
H47: 2876.31 | I47: 0.220651 | J47: 2.30326 | K47: 0.0167605 | S47: 2876.84 | T47: 0.223276 | U47: 2.2983 | V47: 0.0167633
F49: Calculos | Q49: Calculos
F51: densidad relativa | G51: viscosidad cinemática | H51: Qtramo | I51: Qvolumétrico | Q51: densidad relativa | R51: viscosidad cinemática | S51: Qtramo | T51: Qvolumétrico
F52: =1/I47 -> 4.5320438 | G52: =(K47*10^(-3))/(F52*10^(-6)) -> 3.6982211 | H52: =Data!I10-Data!H6*(Data!D6+Data!C6) -> 3056.3 | I52: =H52/F52 -> 674.37565 | Q52: =1/T47 -> 4.4787617 | R52: =(V47*10^(-3))/(Q52*10^(-6)) -> 3.7428426 | S52: =Data!I10-Data!H6*(Data!C6+Data!D6+Data!F6) -> 712.6 | T52: =S52/Q52 -> 159.10648
...

Sheet Red de condensados
F1: RED DE CONDENSADOS
B2: valor cte
A5: Hay que aprovechar el vapor flash, sobretodo porque pusimos una caldera sin economizador | D5: Predcondensados[bar(g)]
D6: =Data!C7-1 -> 3 | I6: 1: Vapor
I7: 2: Condensados
AC10: Linea de condensados | AD10: Lreal(m) | AE10: Dtanteo (mm) | AF10: Leq(m) | AG10: Lcálculo(m) | AH10: Dtubería (mm) | AI10: Pentrada (bar(g)) | AJ10: Psalida (bar(g))
C11: Tramo Caldera-P | O11: Tramo P-C1 | R11: heje[m] | S11: 1.0945 | AC11: Caldera-P | AD11: =$D$13 -> 12.74 | AE11: N/A | AF11: =AD11*0.2 -> 2.548 | AG11: =AD11+AF11 -> 15.288 | AH11: 65 | AI11: =$J$17 -> 3 | AJ11: =$AI12 -> 2.98
AC12: P-C1 | AD12: =$P$13 -> 88.189 | AE12: 30 | AF12: =(2*(32*30)+1*(90*30))/1000 -> 4.62 | AG12: =AD12+AF12 -> 92.809 | AH12: 32 | AI12: =$V$17 -> 2.98 | AJ12: =$AI13 -> 2.73
C13: Lreal(m) | D13: 12.74 | F13: Perdida de carga | O13: Lreal(m) | P13: =40+45+2*$S$11+1 -> 88.189 | R13: Perdida de carga | AC13: P-S | AD13: =$D$33 -> 105 | AE13: 60 | AF13: =(2*(90*60)+1*(32*60))/1000 -> 12.72 | AG13: =AD13+AF13 -> 117.72 | AH13: 65 | AI13: =$J$37 -> 2.73 | AJ13: =$AI14 -> 2.59
C14: Leq | D14: =D13*0.2 -> 2.548 | O14: Leq | P14: =(2*(32*30)+1*(90*30))/1000 -> 4.62 | AC14: S-C2 | AD14: =$P$33 -> 24 | AE14: 45 | AF14: =(32*45+90*45)/1000 -> 5.49 | AG14: =AD14+AF14 -> 29.49 | AH14: 50 | AI14: =$V$37 -> 2.59 | AJ14: =AI15-0.05 -> 2.54
C15: Lcálculo(m) | D15: =D13+D14 -> 15.288 | F15: Tabla | H15: Vapor (vapor saturado) | J15: Condensados | O15: Lcálculo(m) | P15: =P13+P14 -> 92.809 | R15: Tabla | T15: Vapor (vapor saturado) | V15: Condensados | AC15: S-T | AD15: =$D$51 -> 60 | AE15: 50 | AF15: =(1*(90*50)+1*(60*50))/1000 -> 7.5 | AG15: =AD15+AF15 -> 67.5 | AH15: 65 | AI15: =$J$55 -> 2.59 | AJ15: =$AI16 -> 2.51
H16: P[bar(g)] | I16: Tsat[ºC] | J16: P[bar(g)] | K16: Tsat[ºC] | T16: P[bar(g)] | U16: Tsat[ºC] | V16: P[bar(g)] | W16: Tsat[ºC] | AC16: T-C3 | AD16: =$P$51 -> 14 | AE16: N/A | AF16: =0.2*$P$51 -> 2.8 | AG16: =AD16+AF16 -> 16.8 | AH16: 25 | AI16: =$V$55 -> 2.51 | AJ16: =AI16-0.05 -> 2.46
C17: Respecto a la long eq en este caso al tener una tubería corta se puede hacer una estimación empírica donde la longitud equivalente es un 20 % de la longitud real | G17: Entrada con | H17: ='Red de vapor'!H9 -> 9.068 | I17: 180.238 | J17: =D6 -> 3 | K17: 143.732 | O17: Respecto a la long eq en este caso al tener una tubería corta se puede hacer una estimación empírica donde la longitud equivalente es un 20 % de la longitud real | S17: Entrada con | T17: 9.058 | U17: 180.194 | V17: 2.98 | W17: 143.552 | AC17: T-C4 | AD17: =$D$70 -> 44 | AE17: 50 | AF17: =(60*50+2*(32*50))/1000 -> 6.2 | AG17: =AD17+AF17 -> 50.2 | AH17: 50 | AI17: =$J$74 -> 2.51 | AJ17: =AI17-0.06 -> 2.45
AH18: Schedule 40
G20: Salida | H20: hlp1 [KJ/KG] | J20: hlp2 [KJ/KG] | K20: hvp2 [KJ/KG] | L20: vol. Espec vapor [m3/Kg] | M20: vol. Espec agua [m3/Kg] | S20: Salida | T20: hlp1 [KJ/KG] | V20: hlp2 [KJ/KG] | W20: hvp2 [KJ/KG] | X20: vol. Espec vapor [m3/Kg] | Y20: vol. Espec agua [m3/Kg] | AC20: Linea de condensados | AD20: Dinterior (mm) | AE20: v(m/s) | AF20: ∆P(bar)
H21: 764.238 | J21: 605.236 | K21: 2738.21 | L21: 0.460957 | M21: 0.00108369 | T21: 764.047 | V21: 604.462 | W21: 2737.98 | X21: 0.463126 | Y21: 0.00108349 | AC21: Caldera-P | AD21: 58 | AE21: 19.31 | AF21: =$AI11-$AJ11 -> 0.02
L22: =L21/($L$21+$M$21) -> 0.99765456 | M22: =M21/($L$21+$M$21) -> 0.0023454428 | X22: =X21/($X$21+Y$21) -> 0.99766595 | Y22: =Y21/($X$21+Z$21) -> 0.0023395145 | AC22: P-C1 | AD22: 28 | AE22: 17.78 | AF22: =$AI12-$AJ12 -> 0.25
F23: Calculos | R23: Calculos | AC23: P-S | AD23: 58 | AE23: 19.13 | AF23: =$AI13-$AJ13 -> 0.14
AC24: S-C2 | AD24: 39 | AE24: 18.04 | AF24: =$AI14-$AJ14 -> 0.05
F25: densidad relativa | G25: viscosidad cinemática | H25: Qtramo | I25: %vf | J25: Qvaporflash | R25: densidad relativa | S25: viscosidad cinemática | T25: Qtramo | U25: %vf | V25: Qvaporflash | AC25: S-T | AD25: 50 | AE25: 17.7 | AF25: =$AI15-$AJ15 -> 0.08
F26: =1/L21 -> 2.1693997 | G26: =(K21*10^(-3))/(F26*10^(-6)) -> 1262197.1 | H26: =Data!I10 -> 5400 | I26: =(H21-J21)/(K21-J21) -> 0.074544744 | J26: =I26*H26 -> 402.54162 | R26: =1/X21 -> 2.1592396 | S26: =(W21*10^(-3))/(R26*10^(-6)) -> 1268029.7 | T26: =Data!$I$10-Data!$H$6*(Data!$D$6+Data!$E$6+Data!$F$6) -> 1102.45 | U26: =(T21-V21)/(W21-V21) -> 0.074798994 | V26: =U26*T26 -> 82.462151 | AC26: T-C3 | AD26: 24 | AE26: 17.96 | AF26: =$AI16-$AJ16 -> 0.05
AC27: T-C4 | AD27: 48 | AE27: 17.41 | AF27: =$AI17-$AJ17 -> 0.06
C31: Tramo P-S | O31: Tramo S-C2
C33: Lreal(m) | D33: 105 | F33: Perdida de carga | O33: Lreal(m) | P33: 24 | R33: Perdida de carga
C34: Leq | D34: =(2*(90*60)+1*(32*60))/1000 -> 12.72 | O34: Leq | P34: =(32*45+90*45)/1000 -> 5.49
C35: Lcálculo(m) | D35: =D33+D34 -> 117.72 | F35: Tabla | H35: Vapor (vapor saturado) | J35: Condensados | O35: Lcálculo(m) | P35: =P33+P34 -> 29.49 | R35: Tabla | T35: Vapor (vapor saturado) | V35: Condensados
H36: P[bar(g)] | I36: Tsat[ºC] | J36: P[bar(g)] | K36: Tsat[ºC] | T36: P[bar(g)] | U36: Tsat[ºC] | V36: P[bar(g)] | W36: Tsat[ºC]
C37: Respecto a la long eq en este caso al tener una tubería corta se puede hacer una estimación empírica donde la longitud equivalente es un 20 % de la longitud real | G37: Entrada con | H37: 9.058 | I37: 180.238 | J37: =V17-0.25 -> 2.73 | K37: 141.236 | O37: Respecto a la long eq en este caso al tener una tubería corta se puede hacer una estimación empírica donde la longitud equivalente es un 20 % de la longitud real | S37: Entrada con | T37: ='Red de vapor'!$S$26 -> 8.9002963 | V37: =J37-0.14 -> 2.59
G40: Salida | H40: hlp1 [KJ/KG] | J40: hlp2 [KJ/KG] | K40: hvp2 [KJ/KG] | L40: vol. Espec vapor [m3/Kg] | M40: vol. Espec agua [m3/Kg] | S40: Salida | T40: hlp1 [KJ/KG] | V40: hlp2 [KJ/KG] | W40: hvp2 [KJ/KG] | X40: vol. Espec vapor [m3/Kg] | Y40: vol. Espec agua [m3/Kg]
H41: =T21 -> 764.047 | J41: 594.509 | K41: 2735.04 | L41: 0.492137 | M41: 0.00108105 | T41: 764.238
L42: =L41/($L$41+$M$41) -> 0.99780817 | M42: =M41/($L$41+$M$41) -> 0.0021918298 | X42: =X41/($L41+$M41) -> 0 | Y42: =Y41/($L41+$M41) -> 0
F43: Calculos | R43: Calculos
F45: densidad relativa | G45: viscosidad cinemática | H45: Qtramo | I45: %vf | J45: Qvaporflash | R45: densidad relativa | S45: viscosidad cinemática | T45: Qtramo | U45: %vf | V45: Qvaporflash
F46: =1/L41 -> 2.0319545 | G46: =(K41*10^(-3))/(F46*10^(-6)) -> 1346014.4 | H46: =Data!I10-Data!H6*(Data!C6) -> 4619.15 | I46: =(H41-J41)/(K41-J41) -> 0.079203712 | J46: =I46*H46 -> 365.85382 | R46: =1/X41 -> #DIV/0! | S46: =(W41*10^(-3))/(R46*10^(-6)) -> #DIV/0! | T46: ='Red de vapor'!$S$35 -> 1884.45 | U46: =(T41-V41)/(W41-V41) -> #DIV/0! | V46: =U46*T46 -> #DIV/0!
C49: Tramo S-T | O49: Tramo T-C3
C51: Lreal(m) | D51: 60 | F51: Perdida de carga | O51: Lreal(m) | P51: 14 | R51: Perdida de carga
C52: Leq | D52: =(1*(90*50)+1*(60*50))/1000 -> 7.5 | O52: Leq | P52: =0.2*$P$51 -> 2.8
C53: Lcálculo(m) | D53: =D51+D52 -> 67.5 | F53: Tabla | H53: Vapor (vapor saturado) | J53: Condensados | O53: Lcálculo(m) | P53: =P51+P52 -> 16.8 | R53: Tabla | T53: Vapor (vapor saturado) | V53: Condensados
H54: P[bar(g)] | I54: Tsat[ºC] | J54: P[bar(g)] | K54: Tsat[ºC] | T54: P[bar(g)] | U54: Tsat[ºC] | V54: P[bar(g)] | W54: Tsat[ºC]
C55: Respecto a la long eq en este caso al tener una tubería corta se puede hacer una estimación empírica donde la longitud equivalente es un 20 % de la longitud real | G55: Entrada con | H55: ='Red de vapor'!$H$43 -> 8.9002963 | J55: 2.59 | O55: Respecto a la long eq en este caso al tener una tubería corta se puede hacer una estimación empírica donde la longitud equivalente es un 20 % de la longitud real | S55: Entrada con | T55: ='Red de vapor'!$S$43 -> 8.7802963 | V55: =$J$55-0.08 -> 2.51
...
